Traceback (most recent call last):
  File "/Users/carlosdavid/opt/anaconda3/envs/jupyterbook_env/lib/python3.11/site-packages/jupyter_cache/executors/utils.py", line 58, in single_nb_execution
    executenb(
  File "/Users/carlosdavid/opt/anaconda3/envs/jupyterbook_env/lib/python3.11/site-packages/nbclient/client.py", line 1305, in execute
    return NotebookClient(nb=nb, resources=resources, km=km, **kwargs).execute()
           ^^^^^^^^^^^^^^^^^^^^^^^^^^^^^^^^^^^^^^^^^^^^^^^^^^^^^^^^^^^^^^^^^^^^^
  File "/Users/carlosdavid/opt/anaconda3/envs/jupyterbook_env/lib/python3.11/site-packages/jupyter_core/utils/__init__.py", line 165, in wrapped
    return loop.run_until_complete(inner)
           ^^^^^^^^^^^^^^^^^^^^^^^^^^^^^^
  File "/Users/carlosdavid/opt/anaconda3/envs/jupyterbook_env/lib/python3.11/asyncio/base_events.py", line 654, in run_until_complete
    return future.result()
           ^^^^^^^^^^^^^^^
  File "/Users/carlosdavid/opt/anaconda3/envs/jupyterbook_env/lib/python3.11/site-packages/nbclient/client.py", line 705, in async_execute
    await self.async_execute_cell(
  File "/Users/carlosdavid/opt/anaconda3/envs/jupyterbook_env/lib/python3.11/site-packages/nbclient/client.py", line 1058, in async_execute_cell
    await self._check_raise_for_error(cell, cell_index, exec_reply)
  File "/Users/carlosdavid/opt/anaconda3/envs/jupyterbook_env/lib/python3.11/site-packages/nbclient/client.py", line 914, in _check_raise_for_error
    raise CellExecutionError.from_cell_and_msg(cell, exec_reply_content)
nbclient.exceptions.CellExecutionError: An error occurred while executing the following cell:
------------------

# Suppose you've already built mjo_stations
station = mjo_stations.iloc[0]
station_id = station["id"]

print("Downloading:", station_id, station["name"])

# Build URL
url = f"https://www.ncei.noaa.gov/pub/data/igra/data/data-por/{station_id}-data.txt.zip"
print(url)

# Download and unzip
r = requests.get(url)
z = zipfile.ZipFile(io.BytesIO(r.content))
fname = z.namelist()[0]

# Read lines
lines = z.read(fname).decode("utf-8").splitlines()
print("Number of lines:", len(lines))
print("First few lines:\n", "\n".join(lines[:15]))
------------------

----- stdout -----
Downloading: BXM00096315 BRUNEI AIRPORT 1981
https://www.ncei.noaa.gov/pub/data/igra/data/data-por/BXM00096315-data.txt.zip
------------------

[0;31m---------------------------------------------------------------------------[0m
[0;31mSSLEOFError[0m                               Traceback (most recent call last)
File [0;32m~/opt/anaconda3/envs/jupyterbook_env/lib/python3.11/site-packages/urllib3/connectionpool.py:466[0m, in [0;36mHTTPConnectionPool._make_request[0;34m(self, conn, method, url, body, headers, retries, timeout, chunked, response_conn, preload_content, decode_content, enforce_content_length)[0m
[1;32m    465[0m [38;5;28;01mtry[39;00m:
[0;32m--> 466[0m     [38;5;28mself[39m[38;5;241m.[39m_validate_conn(conn)
[1;32m    467[0m [38;5;28;01mexcept[39;00m (SocketTimeout, BaseSSLError) [38;5;28;01mas[39;00m e:

File [0;32m~/opt/anaconda3/envs/jupyterbook_env/lib/python3.11/site-packages/urllib3/connectionpool.py:1095[0m, in [0;36mHTTPSConnectionPool._validate_conn[0;34m(self, conn)[0m
[1;32m   1094[0m [38;5;28;01mif[39;00m conn[38;5;241m.[39mis_closed:
[0;32m-> 1095[0m     conn[38;5;241m.[39mconnect()
[1;32m   1097[0m [38;5;66;03m# TODO revise this, see https://github.com/urllib3/urllib3/issues/2791[39;00m

File [0;32m~/opt/anaconda3/envs/jupyterbook_env/lib/python3.11/site-packages/urllib3/connection.py:730[0m, in [0;36mHTTPSConnection.connect[0;34m(self)[0m
[1;32m    728[0m server_hostname_rm_dot [38;5;241m=[39m server_hostname[38;5;241m.[39mrstrip([38;5;124m"[39m[38;5;124m.[39m[38;5;124m"[39m)
[0;32m--> 730[0m sock_and_verified [38;5;241m=[39m _ssl_wrap_socket_and_match_hostname(
[1;32m    731[0m     sock[38;5;241m=[39msock,
[1;32m    732[0m     cert_reqs[38;5;241m=[39m[38;5;28mself[39m[38;5;241m.[39mcert_reqs,
[1;32m    733[0m     ssl_version[38;5;241m=[39m[38;5;28mself[39m[38;5;241m.[39mssl_version,
[1;32m    734[0m     ssl_minimum_version[38;5;241m=[39m[38;5;28mself[39m[38;5;241m.[39mssl_minimum_version,
[1;32m    735[0m     ssl_maximum_version[38;5;241m=[39m[38;5;28mself[39m[38;5;241m.[39mssl_maximum_version,
[1;32m    736[0m     ca_certs[38;5;241m=[39m[38;5;28mself[39m[38;5;241m.[39mca_certs,
[1;32m    737[0m     ca_cert_dir[38;5;241m=[39m[38;5;28mself[39m[38;5;241m.[39mca_cert_dir,
[1;32m    738[0m     ca_cert_data[38;5;241m=[39m[38;5;28mself[39m[38;5;241m.[39mca_cert_data,
[1;32m    739[0m     cert_file[38;5;241m=[39m[38;5;28mself[39m[38;5;241m.[39mcert_file,
[1;32m    740[0m     key_file[38;5;241m=[39m[38;5;28mself[39m[38;5;241m.[39mkey_file,
[1;32m    741[0m     key_password[38;5;241m=[39m[38;5;28mself[39m[38;5;241m.[39mkey_password,
[1;32m    742[0m     server_hostname[38;5;241m=[39mserver_hostname_rm_dot,
[1;32m    743[0m     ssl_context[38;5;241m=[39m[38;5;28mself[39m[38;5;241m.[39mssl_context,
[1;32m    744[0m     tls_in_tls[38;5;241m=[39mtls_in_tls,
[1;32m    745[0m     assert_hostname[38;5;241m=[39m[38;5;28mself[39m[38;5;241m.[39massert_hostname,
[1;32m    746[0m     assert_fingerprint[38;5;241m=[39m[38;5;28mself[39m[38;5;241m.[39massert_fingerprint,
[1;32m    747[0m )
[1;32m    748[0m [38;5;28mself[39m[38;5;241m.[39msock [38;5;241m=[39m sock_and_verified[38;5;241m.[39msocket

File [0;32m~/opt/anaconda3/envs/jupyterbook_env/lib/python3.11/site-packages/urllib3/connection.py:909[0m, in [0;36m_ssl_wrap_socket_and_match_hostname[0;34m(sock, cert_reqs, ssl_version, ssl_minimum_version, ssl_maximum_version, cert_file, key_file, key_password, ca_certs, ca_cert_dir, ca_cert_data, assert_hostname, assert_fingerprint, server_hostname, ssl_context, tls_in_tls)[0m
[1;32m    907[0m         server_hostname [38;5;241m=[39m normalized
[0;32m--> 909[0m ssl_sock [38;5;241m=[39m ssl_wrap_socket(
[1;32m    910[0m     sock[38;5;241m=[39msock,
[1;32m    911[0m     keyfile[38;5;241m=[39mkey_file,
[1;32m    912[0m     certfile[38;5;241m=[39mcert_file,
[1;32m    913[0m     key_password[38;5;241m=[39mkey_password,
[1;32m    914[0m     ca_certs[38;5;241m=[39mca_certs,
[1;32m    915[0m     ca_cert_dir[38;5;241m=[39mca_cert_dir,
[1;32m    916[0m     ca_cert_data[38;5;241m=[39mca_cert_data,
[1;32m    917[0m     server_hostname[38;5;241m=[39mserver_hostname,
[1;32m    918[0m     ssl_context[38;5;241m=[39mcontext,
[1;32m    919[0m     tls_in_tls[38;5;241m=[39mtls_in_tls,
[1;32m    920[0m )
[1;32m    922[0m [38;5;28;01mtry[39;00m:

File [0;32m~/opt/anaconda3/envs/jupyterbook_env/lib/python3.11/site-packages/urllib3/util/ssl_.py:469[0m, in [0;36mssl_wrap_socket[0;34m(sock, keyfile, certfile, cert_reqs, ca_certs, server_hostname, ssl_version, ciphers, ssl_context, ca_cert_dir, key_password, ca_cert_data, tls_in_tls)[0m
[1;32m    467[0m context[38;5;241m.[39mset_alpn_protocols(ALPN_PROTOCOLS)
[0;32m--> 469[0m ssl_sock [38;5;241m=[39m _ssl_wrap_socket_impl(sock, context, tls_in_tls, server_hostname)
[1;32m    470[0m [38;5;28;01mreturn[39;00m ssl_sock

File [0;32m~/opt/anaconda3/envs/jupyterbook_env/lib/python3.11/site-packages/urllib3/util/ssl_.py:513[0m, in [0;36m_ssl_wrap_socket_impl[0;34m(sock, ssl_context, tls_in_tls, server_hostname)[0m
[1;32m    511[0m     [38;5;28;01mreturn[39;00m SSLTransport(sock, ssl_context, server_hostname)
[0;32m--> 513[0m [38;5;28;01mreturn[39;00m ssl_context[38;5;241m.[39mwrap_socket(sock, server_hostname[38;5;241m=[39mserver_hostname)

File [0;32m~/opt/anaconda3/envs/jupyterbook_env/lib/python3.11/ssl.py:517[0m, in [0;36mSSLContext.wrap_socket[0;34m(self, sock, server_side, do_handshake_on_connect, suppress_ragged_eofs, server_hostname, session)[0m
[1;32m    511[0m [38;5;28;01mdef[39;00m [38;5;21mwrap_socket[39m([38;5;28mself[39m, sock, server_side[38;5;241m=[39m[38;5;28;01mFalse[39;00m,
[1;32m    512[0m                 do_handshake_on_connect[38;5;241m=[39m[38;5;28;01mTrue[39;00m,
[1;32m    513[0m                 suppress_ragged_eofs[38;5;241m=[39m[38;5;28;01mTrue[39;00m,
[1;32m    514[0m                 server_hostname[38;5;241m=[39m[38;5;28;01mNone[39;00m, session[38;5;241m=[39m[38;5;28;01mNone[39;00m):
[1;32m    515[0m     [38;5;66;03m# SSLSocket class handles server_hostname encoding before it calls[39;00m
[1;32m    516[0m     [38;5;66;03m# ctx._wrap_socket()[39;00m
[0;32m--> 517[0m     [38;5;28;01mreturn[39;00m [38;5;28mself[39m[38;5;241m.[39msslsocket_class[38;5;241m.[39m_create(
[1;32m    518[0m         sock[38;5;241m=[39msock,
[1;32m    519[0m         server_side[38;5;241m=[39mserver_side,
[1;32m    520[0m         do_handshake_on_connect[38;5;241m=[39mdo_handshake_on_connect,
[1;32m    521[0m         suppress_ragged_eofs[38;5;241m=[39msuppress_ragged_eofs,
[1;32m    522[0m         server_hostname[38;5;241m=[39mserver_hostname,
[1;32m    523[0m         context[38;5;241m=[39m[38;5;28mself[39m,
[1;32m    524[0m         session[38;5;241m=[39msession
[1;32m    525[0m     )

File [0;32m~/opt/anaconda3/envs/jupyterbook_env/lib/python3.11/ssl.py:1104[0m, in [0;36mSSLSocket._create[0;34m(cls, sock, server_side, do_handshake_on_connect, suppress_ragged_eofs, server_hostname, context, session)[0m
[1;32m   1103[0m                 [38;5;28;01mraise[39;00m [38;5;167;01mValueError[39;00m([38;5;124m"[39m[38;5;124mdo_handshake_on_connect should not be specified for non-blocking sockets[39m[38;5;124m"[39m)
[0;32m-> 1104[0m             [38;5;28mself[39m[38;5;241m.[39mdo_handshake()
[1;32m   1105[0m [38;5;28;01mexcept[39;00m:

File [0;32m~/opt/anaconda3/envs/jupyterbook_env/lib/python3.11/ssl.py:1382[0m, in [0;36mSSLSocket.do_handshake[0;34m(self, block)[0m
[1;32m   1381[0m         [38;5;28mself[39m[38;5;241m.[39msettimeout([38;5;28;01mNone[39;00m)
[0;32m-> 1382[0m     [38;5;28mself[39m[38;5;241m.[39m_sslobj[38;5;241m.[39mdo_handshake()
[1;32m   1383[0m [38;5;28;01mfinally[39;00m:

[0;31mSSLEOFError[0m: [SSL: UNEXPECTED_EOF_WHILE_READING] EOF occurred in violation of protocol (_ssl.c:1006)

During handling of the above exception, another exception occurred:

[0;31mSSLError[0m                                  Traceback (most recent call last)
File [0;32m~/opt/anaconda3/envs/jupyterbook_env/lib/python3.11/site-packages/urllib3/connectionpool.py:789[0m, in [0;36mHTTPConnectionPool.urlopen[0;34m(self, method, url, body, headers, retries, redirect, assert_same_host, timeout, pool_timeout, release_conn, chunked, body_pos, preload_content, decode_content, **response_kw)[0m
[1;32m    788[0m [38;5;66;03m# Make the request on the HTTPConnection object[39;00m
[0;32m--> 789[0m response [38;5;241m=[39m [38;5;28mself[39m[38;5;241m.[39m_make_request(
[1;32m    790[0m     conn,
[1;32m    791[0m     method,
[1;32m    792[0m     url,
[1;32m    793[0m     timeout[38;5;241m=[39mtimeout_obj,
[1;32m    794[0m     body[38;5;241m=[39mbody,
[1;32m    795[0m     headers[38;5;241m=[39mheaders,
[1;32m    796[0m     chunked[38;5;241m=[39mchunked,
[1;32m    797[0m     retries[38;5;241m=[39mretries,
[1;32m    798[0m     response_conn[38;5;241m=[39mresponse_conn,
[1;32m    799[0m     preload_content[38;5;241m=[39mpreload_content,
[1;32m    800[0m     decode_content[38;5;241m=[39mdecode_content,
[1;32m    801[0m     [38;5;241m*[39m[38;5;241m*[39mresponse_kw,
[1;32m    802[0m )
[1;32m    804[0m [38;5;66;03m# Everything went great![39;00m

File [0;32m~/opt/anaconda3/envs/jupyterbook_env/lib/python3.11/site-packages/urllib3/connectionpool.py:490[0m, in [0;36mHTTPConnectionPool._make_request[0;34m(self, conn, method, url, body, headers, retries, timeout, chunked, response_conn, preload_content, decode_content, enforce_content_length)[0m
[1;32m    489[0m         new_e [38;5;241m=[39m _wrap_proxy_error(new_e, conn[38;5;241m.[39mproxy[38;5;241m.[39mscheme)
[0;32m--> 490[0m     [38;5;28;01mraise[39;00m new_e
[1;32m    492[0m [38;5;66;03m# conn.request() calls http.client.*.request, not the method in[39;00m
[1;32m    493[0m [38;5;66;03m# urllib3.request. It also calls makefile (recv) on the socket.[39;00m

[0;31mSSLError[0m: [SSL: UNEXPECTED_EOF_WHILE_READING] EOF occurred in violation of protocol (_ssl.c:1006)

The above exception was the direct cause of the following exception:

[0;31mMaxRetryError[0m                             Traceback (most recent call last)
File [0;32m~/opt/anaconda3/envs/jupyterbook_env/lib/python3.11/site-packages/requests/adapters.py:667[0m, in [0;36mHTTPAdapter.send[0;34m(self, request, stream, timeout, verify, cert, proxies)[0m
[1;32m    666[0m [38;5;28;01mtry[39;00m:
[0;32m--> 667[0m     resp [38;5;241m=[39m conn[38;5;241m.[39murlopen(
[1;32m    668[0m         method[38;5;241m=[39mrequest[38;5;241m.[39mmethod,
[1;32m    669[0m         url[38;5;241m=[39murl,
[1;32m    670[0m         body[38;5;241m=[39mrequest[38;5;241m.[39mbody,
[1;32m    671[0m         headers[38;5;241m=[39mrequest[38;5;241m.[39mheaders,
[1;32m    672[0m         redirect[38;5;241m=[39m[38;5;28;01mFalse[39;00m,
[1;32m    673[0m         assert_same_host[38;5;241m=[39m[38;5;28;01mFalse[39;00m,
[1;32m    674[0m         preload_content[38;5;241m=[39m[38;5;28;01mFalse[39;00m,
[1;32m    675[0m         decode_content[38;5;241m=[39m[38;5;28;01mFalse[39;00m,
[1;32m    676[0m         retries[38;5;241m=[39m[38;5;28mself[39m[38;5;241m.[39mmax_retries,
[1;32m    677[0m         timeout[38;5;241m=[39mtimeout,
[1;32m    678[0m         chunked[38;5;241m=[39mchunked,
[1;32m    679[0m     )
[1;32m    681[0m [38;5;28;01mexcept[39;00m (ProtocolError, [38;5;167;01mOSError[39;00m) [38;5;28;01mas[39;00m err:

File [0;32m~/opt/anaconda3/envs/jupyterbook_env/lib/python3.11/site-packages/urllib3/connectionpool.py:843[0m, in [0;36mHTTPConnectionPool.urlopen[0;34m(self, method, url, body, headers, retries, redirect, assert_same_host, timeout, pool_timeout, release_conn, chunked, body_pos, preload_content, decode_content, **response_kw)[0m
[1;32m    841[0m     new_e [38;5;241m=[39m ProtocolError([38;5;124m"[39m[38;5;124mConnection aborted.[39m[38;5;124m"[39m, new_e)
[0;32m--> 843[0m retries [38;5;241m=[39m retries[38;5;241m.[39mincrement(
[1;32m    844[0m     method, url, error[38;5;241m=[39mnew_e, _pool[38;5;241m=[39m[38;5;28mself[39m, _stacktrace[38;5;241m=[39msys[38;5;241m.[39mexc_info()[[38;5;241m2[39m]
[1;32m    845[0m )
[1;32m    846[0m retries[38;5;241m.[39msleep()

File [0;32m~/opt/anaconda3/envs/jupyterbook_env/lib/python3.11/site-packages/urllib3/util/retry.py:519[0m, in [0;36mRetry.increment[0;34m(self, method, url, response, error, _pool, _stacktrace)[0m
[1;32m    518[0m     reason [38;5;241m=[39m error [38;5;129;01mor[39;00m ResponseError(cause)
[0;32m--> 519[0m     [38;5;28;01mraise[39;00m MaxRetryError(_pool, url, reason) [38;5;28;01mfrom[39;00m [38;5;21;01mreason[39;00m  [38;5;66;03m# type: ignore[arg-type][39;00m
[1;32m    521[0m log[38;5;241m.[39mdebug([38;5;124m"[39m[38;5;124mIncremented Retry for (url=[39m[38;5;124m'[39m[38;5;132;01m%s[39;00m[38;5;124m'[39m[38;5;124m): [39m[38;5;132;01m%r[39;00m[38;5;124m"[39m, url, new_retry)

[0;31mMaxRetryError[0m: HTTPSConnectionPool(host='www.ncei.noaa.gov', port=443): Max retries exceeded with url: /pub/data/igra/data/data-por/BXM00096315-data.txt.zip (Caused by SSLError(SSLEOFError(8, '[SSL: UNEXPECTED_EOF_WHILE_READING] EOF occurred in violation of protocol (_ssl.c:1006)')))

During handling of the above exception, another exception occurred:

[0;31mSSLError[0m                                  Traceback (most recent call last)
Cell [0;32mIn[6], line 12[0m
[1;32m      9[0m [38;5;28mprint[39m(url)
[1;32m     11[0m [38;5;66;03m# Download and unzip[39;00m
[0;32m---> 12[0m r [38;5;241m=[39m requests[38;5;241m.[39mget(url)
[1;32m     13[0m z [38;5;241m=[39m zipfile[38;5;241m.[39mZipFile(io[38;5;241m.[39mBytesIO(r[38;5;241m.[39mcontent))
[1;32m     14[0m fname [38;5;241m=[39m z[38;5;241m.[39mnamelist()[[38;5;241m0[39m]

File [0;32m~/opt/anaconda3/envs/jupyterbook_env/lib/python3.11/site-packages/requests/api.py:73[0m, in [0;36mget[0;34m(url, params, **kwargs)[0m
[1;32m     62[0m [38;5;28;01mdef[39;00m [38;5;21mget[39m(url, params[38;5;241m=[39m[38;5;28;01mNone[39;00m, [38;5;241m*[39m[38;5;241m*[39mkwargs):
[1;32m     63[0m [38;5;250m    [39m[38;5;124mr[39m[38;5;124;03m"""Sends a GET request.[39;00m
[1;32m     64[0m 
[1;32m     65[0m [38;5;124;03m    :param url: URL for the new :class:`Request` object.[39;00m
[0;32m   (...)[0m
[1;32m     70[0m [38;5;124;03m    :rtype: requests.Response[39;00m
[1;32m     71[0m [38;5;124;03m    """[39;00m
[0;32m---> 73[0m     [38;5;28;01mreturn[39;00m request([38;5;124m"[39m[38;5;124mget[39m[38;5;124m"[39m, url, params[38;5;241m=[39mparams, [38;5;241m*[39m[38;5;241m*[39mkwargs)

File [0;32m~/opt/anaconda3/envs/jupyterbook_env/lib/python3.11/site-packages/requests/api.py:59[0m, in [0;36mrequest[0;34m(method, url, **kwargs)[0m
[1;32m     55[0m [38;5;66;03m# By using the 'with' statement we are sure the session is closed, thus we[39;00m
[1;32m     56[0m [38;5;66;03m# avoid leaving sockets open which can trigger a ResourceWarning in some[39;00m
[1;32m     57[0m [38;5;66;03m# cases, and look like a memory leak in others.[39;00m
[1;32m     58[0m [38;5;28;01mwith[39;00m sessions[38;5;241m.[39mSession() [38;5;28;01mas[39;00m session:
[0;32m---> 59[0m     [38;5;28;01mreturn[39;00m session[38;5;241m.[39mrequest(method[38;5;241m=[39mmethod, url[38;5;241m=[39murl, [38;5;241m*[39m[38;5;241m*[39mkwargs)

File [0;32m~/opt/anaconda3/envs/jupyterbook_env/lib/python3.11/site-packages/requests/sessions.py:589[0m, in [0;36mSession.request[0;34m(self, method, url, params, data, headers, cookies, files, auth, timeout, allow_redirects, proxies, hooks, stream, verify, cert, json)[0m
[1;32m    584[0m send_kwargs [38;5;241m=[39m {
[1;32m    585[0m     [38;5;124m"[39m[38;5;124mtimeout[39m[38;5;124m"[39m: timeout,
[1;32m    586[0m     [38;5;124m"[39m[38;5;124mallow_redirects[39m[38;5;124m"[39m: allow_redirects,
[1;32m    587[0m }
[1;32m    588[0m send_kwargs[38;5;241m.[39mupdate(settings)
[0;32m--> 589[0m resp [38;5;241m=[39m [38;5;28mself[39m[38;5;241m.[39msend(prep, [38;5;241m*[39m[38;5;241m*[39msend_kwargs)
[1;32m    591[0m [38;5;28;01mreturn[39;00m resp

File [0;32m~/opt/anaconda3/envs/jupyterbook_env/lib/python3.11/site-packages/requests/sessions.py:703[0m, in [0;36mSession.send[0;34m(self, request, **kwargs)[0m
[1;32m    700[0m start [38;5;241m=[39m preferred_clock()
[1;32m    702[0m [38;5;66;03m# Send the request[39;00m
[0;32m--> 703[0m r [38;5;241m=[39m adapter[38;5;241m.[39msend(request, [38;5;241m*[39m[38;5;241m*[39mkwargs)
[1;32m    705[0m [38;5;66;03m# Total elapsed time of the request (approximately)[39;00m
[1;32m    706[0m elapsed [38;5;241m=[39m preferred_clock() [38;5;241m-[39m start

File [0;32m~/opt/anaconda3/envs/jupyterbook_env/lib/python3.11/site-packages/requests/adapters.py:698[0m, in [0;36mHTTPAdapter.send[0;34m(self, request, stream, timeout, verify, cert, proxies)[0m
[1;32m    694[0m         [38;5;28;01mraise[39;00m ProxyError(e, request[38;5;241m=[39mrequest)
[1;32m    696[0m     [38;5;28;01mif[39;00m [38;5;28misinstance[39m(e[38;5;241m.[39mreason, _SSLError):
[1;32m    697[0m         [38;5;66;03m# This branch is for urllib3 v1.22 and later.[39;00m
[0;32m--> 698[0m         [38;5;28;01mraise[39;00m SSLError(e, request[38;5;241m=[39mrequest)
[1;32m    700[0m     [38;5;28;01mraise[39;00m [38;5;167;01mConnectionError[39;00m(e, request[38;5;241m=[39mrequest)
[1;32m    702[0m [38;5;28;01mexcept[39;00m ClosedPoolError [38;5;28;01mas[39;00m e:

[0;31mSSLError[0m: HTTPSConnectionPool(host='www.ncei.noaa.gov', port=443): Max retries exceeded with url: /pub/data/igra/data/data-por/BXM00096315-data.txt.zip (Caused by SSLError(SSLEOFError(8, '[SSL: UNEXPECTED_EOF_WHILE_READING] EOF occurred in violation of protocol (_ssl.c:1006)')))

