Traceback (most recent call last):
  File "/Users/carlosdavid/opt/anaconda3/envs/jupyterbook_env/lib/python3.11/site-packages/jupyter_cache/executors/utils.py", line 58, in single_nb_execution
    executenb(
  File "/Users/carlosdavid/opt/anaconda3/envs/jupyterbook_env/lib/python3.11/site-packages/nbclient/client.py", line 1305, in execute
    return NotebookClient(nb=nb, resources=resources, km=km, **kwargs).execute()
           ^^^^^^^^^^^^^^^^^^^^^^^^^^^^^^^^^^^^^^^^^^^^^^^^^^^^^^^^^^^^^^^^^^^^^
  File "/Users/carlosdavid/opt/anaconda3/envs/jupyterbook_env/lib/python3.11/site-packages/jupyter_core/utils/__init__.py", line 165, in wrapped
    return loop.run_until_complete(inner)
           ^^^^^^^^^^^^^^^^^^^^^^^^^^^^^^
  File "/Users/carlosdavid/opt/anaconda3/envs/jupyterbook_env/lib/python3.11/asyncio/base_events.py", line 654, in run_until_complete
    return future.result()
           ^^^^^^^^^^^^^^^
  File "/Users/carlosdavid/opt/anaconda3/envs/jupyterbook_env/lib/python3.11/site-packages/nbclient/client.py", line 705, in async_execute
    await self.async_execute_cell(
  File "/Users/carlosdavid/opt/anaconda3/envs/jupyterbook_env/lib/python3.11/site-packages/nbclient/client.py", line 1058, in async_execute_cell
    await self._check_raise_for_error(cell, cell_index, exec_reply)
  File "/Users/carlosdavid/opt/anaconda3/envs/jupyterbook_env/lib/python3.11/site-packages/nbclient/client.py", line 914, in _check_raise_for_error
    raise CellExecutionError.from_cell_and_msg(cell, exec_reply_content)
nbclient.exceptions.CellExecutionError: An error occurred while executing the following cell:
------------------
# Fetch RMM and show phase-space plot
rmm = fetch_rmm()  # optionally: fetch_rmm(max_age_days=365)
fig = plot_rmm_phase_space(rmm, highlight_days=60)
fig.show()

# (Optional) display a quick table of the last few days
rmm.tail()

------------------


[0;31m---------------------------------------------------------------------------[0m
[0;31mRuntimeError[0m                              Traceback (most recent call last)
Cell [0;32mIn[3], line 2[0m
[1;32m      1[0m [38;5;66;03m# Fetch RMM and show phase-space plot[39;00m
[0;32m----> 2[0m rmm [38;5;241m=[39m fetch_rmm()  [38;5;66;03m# optionally: fetch_rmm(max_age_days=365)[39;00m
[1;32m      3[0m fig [38;5;241m=[39m plot_rmm_phase_space(rmm, highlight_days[38;5;241m=[39m[38;5;241m60[39m)
[1;32m      4[0m fig[38;5;241m.[39mshow()

Cell [0;32mIn[2], line 31[0m, in [0;36mfetch_rmm[0;34m(max_age_days)[0m
[1;32m     28[0m         [38;5;28;01mcontinue[39;00m
[1;32m     30[0m [38;5;28;01mif[39;00m text [38;5;129;01mis[39;00m [38;5;28;01mNone[39;00m:
[0;32m---> 31[0m     [38;5;28;01mraise[39;00m [38;5;167;01mRuntimeError[39;00m([38;5;124mf[39m[38;5;124m"[39m[38;5;124mFailed to download RMM data: [39m[38;5;132;01m{[39;00mlast_error[38;5;132;01m!r}[39;00m[38;5;124m"[39m)
[1;32m     33[0m rows [38;5;241m=[39m []
[1;32m     34[0m [38;5;28;01mfor[39;00m raw [38;5;129;01min[39;00m text[38;5;241m.[39msplitlines():

[0;31mRuntimeError[0m: Failed to download RMM data: HTTPError('403 Client Error: Forbidden for url: http://www.bom.gov.au/climate/mjo/graphics/rmm.74toRealtime.txt')

